<robot name = "robot">
    <link name="Body">
        <inertial>
            <origin xyz="0 0 6.091779436130064" rpy="0 0 0"/>
            <mass value="1" />
            <inertia ixx="100" ixy="0" ixz="0" iyy="100" iyz="0" izz="100" />
        </inertial>
        <visual>
            <origin xyz="0 0 6.091779436130064" rpy="0 0 0"/>
            <geometry>
                <box size="3.786865606638533 4.11903451496744 3.287424168961297" />
            </geometry>
            <material name="Cyan">
                <color rgba="0 1.0 1.0 1.0"/>
            </material>
        </visual>
        <collision>
            <origin xyz="0 0 6.091779436130064" rpy="0 0 0"/>
            <geometry>
                <box size="3.786865606638533 4.11903451496744 3.287424168961297" />
            </geometry>
        </collision>
    </link>
    <joint name="Body_Leg1" type="revolute">
       <parent link="Body"/>
       <child  link="Leg1"/>
       <origin rpy="0 0 0" xyz="-1.8934328033192664 -2.05951725748372 4.448067351649415" />
       <axis xyz="0 1 0"/>
       <limit effort="0.0" lower="-3.14159" upper="3.14159" velocity="0.0"/>
    </joint>
    <link name="Leg1">
        <inertial>
            <origin xyz="-0.0253407824686952 -0.06573577409531711 -1.3728250507852144" rpy="0 0 0"/>
            <mass value="1" />
            <inertia ixx="100" ixy="0" ixz="0" iyy="100" iyz="0" izz="100" />
        </inertial>
        <visual>
            <origin xyz="-0.0253407824686952 -0.06573577409531711 -1.3728250507852144" rpy="0 0 0"/>
            <geometry>
                <box size="0.0506815649373904 0.13147154819063422 2.745650101570429" />
            </geometry>
            <material name="Cyan">
                <color rgba="0 1.0 1.0 1.0"/>
            </material>
        </visual>
        <collision>
            <origin xyz="-0.0253407824686952 -0.06573577409531711 -1.3728250507852144" rpy="0 0 0"/>
            <geometry>
                <box size="0.0506815649373904 0.13147154819063422 2.745650101570429" />
            </geometry>
        </collision>
    </link>
    <joint name="Body_Leg2" type="revolute">
       <parent link="Body"/>
       <child  link="Leg2"/>
       <origin rpy="0 0 0" xyz="1.8934328033192664 -2.05951725748372 4.448067351649415" />
       <axis xyz="0 1 0"/>
       <limit effort="0.0" lower="-3.14159" upper="3.14159" velocity="0.0"/>
    </joint>
    <link name="Leg2">
        <inertial>
            <origin xyz="1.2240406005674456 -1.5935816327933043 -2.2240336758247077" rpy="0 0 0"/>
            <mass value="1" />
            <inertia ixx="100" ixy="0" ixz="0" iyy="100" iyz="0" izz="100" />
        </inertial>
        <visual>
            <origin xyz="1.2240406005674456 -1.5935816327933043 -2.2240336758247077" rpy="0 0 0"/>
            <geometry>
                <box size="2.448081201134891 3.1871632655866087 4.448067351649415" />
            </geometry>
            <material name="Cyan">
                <color rgba="0 1.0 1.0 1.0"/>
            </material>
        </visual>
        <collision>
            <origin xyz="1.2240406005674456 -1.5935816327933043 -2.2240336758247077" rpy="0 0 0"/>
            <geometry>
                <box size="2.448081201134891 3.1871632655866087 4.448067351649415" />
            </geometry>
        </collision>
    </link>
    <joint name="Body_Leg3" type="revolute">
       <parent link="Body"/>
       <child  link="Leg3"/>
       <origin rpy="0 0 0" xyz="1.8934328033192664 2.05951725748372 4.448067351649415" />
       <axis xyz="0 1 0"/>
       <limit effort="0.0" lower="-3.14159" upper="3.14159" velocity="0.0"/>
    </joint>
    <link name="Leg3">
        <inertial>
            <origin xyz="0.857136209542072 0.9353337993321695 -1.420975804730089" rpy="0 0 0"/>
            <mass value="1" />
            <inertia ixx="100" ixy="0" ixz="0" iyy="100" iyz="0" izz="100" />
        </inertial>
        <visual>
            <origin xyz="0.857136209542072 0.9353337993321695 -1.420975804730089" rpy="0 0 0"/>
            <geometry>
                <box size="1.714272419084144 1.870667598664339 2.841951609460178" />
            </geometry>
            <material name="Cyan">
                <color rgba="0 1.0 1.0 1.0"/>
            </material>
        </visual>
        <collision>
            <origin xyz="0.857136209542072 0.9353337993321695 -1.420975804730089" rpy="0 0 0"/>
            <geometry>
                <box size="1.714272419084144 1.870667598664339 2.841951609460178" />
            </geometry>
        </collision>
    </link>
    <joint name="Body_Leg4" type="revolute">
       <parent link="Body"/>
       <child  link="Leg4"/>
       <origin rpy="0 0 0" xyz="-1.8934328033192664 2.05951725748372 4.448067351649415" />
       <axis xyz="0 1 0"/>
       <limit effort="0.0" lower="-3.14159" upper="3.14159" velocity="0.0"/>
    </joint>
    <link name="Leg4">
        <inertial>
            <origin xyz="-2.1776995575046763 1.9795758119672406 -0.7921302049821302" rpy="0 0 0"/>
            <mass value="1" />
            <inertia ixx="100" ixy="0" ixz="0" iyy="100" iyz="0" izz="100" />
        </inertial>
        <visual>
            <origin xyz="-2.1776995575046763 1.9795758119672406 -0.7921302049821302" rpy="0 0 0"/>
            <geometry>
                <box size="4.3553991150093525 3.9591516239344813 1.5842604099642603" />
            </geometry>
            <material name="Cyan">
                <color rgba="0 1.0 1.0 1.0"/>
            </material>
        </visual>
        <collision>
            <origin xyz="-2.1776995575046763 1.9795758119672406 -0.7921302049821302" rpy="0 0 0"/>
            <geometry>
                <box size="4.3553991150093525 3.9591516239344813 1.5842604099642603" />
            </geometry>
        </collision>
    </link>
</robot>