<robot name = "robot">
    <link name="Body">
        <inertial>
            <origin xyz="0 0 4.60947570692541" rpy="0 0 0"/>
            <mass value="1" />
            <inertia ixx="100" ixy="0" ixz="0" iyy="100" iyz="0" izz="100" />
        </inertial>
        <visual>
            <origin xyz="0 0 4.60947570692541" rpy="0 0 0"/>
            <geometry>
                <box size="2.5229233022477175 1.4301730994919097 0.8093090993179242" />
            </geometry>
            <material name="Cyan">
                <color rgba="0 1.0 1.0 1.0"/>
            </material>
        </visual>
        <collision>
            <origin xyz="0 0 4.60947570692541" rpy="0 0 0"/>
            <geometry>
                <box size="2.5229233022477175 1.4301730994919097 0.8093090993179242" />
            </geometry>
        </collision>
    </link>
    <joint name="Body_Leg1" type="revolute">
       <parent link="Body"/>
       <child  link="Leg1"/>
       <origin rpy="0 0 0" xyz="-1.2614616511238588 -0.7150865497459549 4.204821157266449" />
       <axis xyz="0 1 0"/>
       <limit effort="0.0" lower="-3.14159" upper="3.14159" velocity="0.0"/>
    </joint>
    <link name="Leg1">
        <inertial>
            <origin xyz="-1.9457816731581503 -0.675321221005011 -0.7085598329403107" rpy="0 0 0"/>
            <mass value="1" />
            <inertia ixx="100" ixy="0" ixz="0" iyy="100" iyz="0" izz="100" />
        </inertial>
        <visual>
            <origin xyz="-1.9457816731581503 -0.675321221005011 -0.7085598329403107" rpy="0 0 0"/>
            <geometry>
                <box size="3.8915633463163006 1.350642442010022 1.4171196658806213" />
            </geometry>
            <material name="Cyan">
                <color rgba="0 1.0 1.0 1.0"/>
            </material>
        </visual>
        <collision>
            <origin xyz="-1.9457816731581503 -0.675321221005011 -0.7085598329403107" rpy="0 0 0"/>
            <geometry>
                <box size="3.8915633463163006 1.350642442010022 1.4171196658806213" />
            </geometry>
        </collision>
    </link>
    <joint name="Body_Leg2" type="revolute">
       <parent link="Body"/>
       <child  link="Leg2"/>
       <origin rpy="0 0 0" xyz="1.2614616511238588 -0.7150865497459549 4.204821157266449" />
       <axis xyz="0 1 0"/>
       <limit effort="0.0" lower="-3.14159" upper="3.14159" velocity="0.0"/>
    </joint>
    <link name="Leg2">
        <inertial>
            <origin xyz="1.3843341099984476 -2.1509157602931337 -1.760531046124699" rpy="0 0 0"/>
            <mass value="1" />
            <inertia ixx="100" ixy="0" ixz="0" iyy="100" iyz="0" izz="100" />
        </inertial>
        <visual>
            <origin xyz="1.3843341099984476 -2.1509157602931337 -1.760531046124699" rpy="0 0 0"/>
            <geometry>
                <box size="2.7686682199968953 4.301831520586267 3.521062092249398" />
            </geometry>
            <material name="Cyan">
                <color rgba="0 1.0 1.0 1.0"/>
            </material>
        </visual>
        <collision>
            <origin xyz="1.3843341099984476 -2.1509157602931337 -1.760531046124699" rpy="0 0 0"/>
            <geometry>
                <box size="2.7686682199968953 4.301831520586267 3.521062092249398" />
            </geometry>
        </collision>
    </link>
    <joint name="Body_Leg3" type="revolute">
       <parent link="Body"/>
       <child  link="Leg3"/>
       <origin rpy="0 0 0" xyz="1.2614616511238588 0.7150865497459549 4.204821157266449" />
       <axis xyz="0 1 0"/>
       <limit effort="0.0" lower="-3.14159" upper="3.14159" velocity="0.0"/>
    </joint>
    <link name="Leg3">
        <inertial>
            <origin xyz="0.22371147210652642 1.4445819965325764 -0.9209693828023993" rpy="0 0 0"/>
            <mass value="1" />
            <inertia ixx="100" ixy="0" ixz="0" iyy="100" iyz="0" izz="100" />
        </inertial>
        <visual>
            <origin xyz="0.22371147210652642 1.4445819965325764 -0.9209693828023993" rpy="0 0 0"/>
            <geometry>
                <box size="0.44742294421305284 2.8891639930651527 1.8419387656047985" />
            </geometry>
            <material name="Cyan">
                <color rgba="0 1.0 1.0 1.0"/>
            </material>
        </visual>
        <collision>
            <origin xyz="0.22371147210652642 1.4445819965325764 -0.9209693828023993" rpy="0 0 0"/>
            <geometry>
                <box size="0.44742294421305284 2.8891639930651527 1.8419387656047985" />
            </geometry>
        </collision>
    </link>
    <joint name="Body_Leg4" type="revolute">
       <parent link="Body"/>
       <child  link="Leg4"/>
       <origin rpy="0 0 0" xyz="-1.2614616511238588 0.7150865497459549 4.204821157266449" />
       <axis xyz="0 1 0"/>
       <limit effort="0.0" lower="-3.14159" upper="3.14159" velocity="0.0"/>
    </joint>
    <link name="Leg4">
        <inertial>
            <origin xyz="-1.8549598277666366 2.446965052237946 -2.1024105786332243" rpy="0 0 0"/>
            <mass value="1" />
            <inertia ixx="100" ixy="0" ixz="0" iyy="100" iyz="0" izz="100" />
        </inertial>
        <visual>
            <origin xyz="-1.8549598277666366 2.446965052237946 -2.1024105786332243" rpy="0 0 0"/>
            <geometry>
                <box size="3.709919655533273 4.893930104475892 4.204821157266449" />
            </geometry>
            <material name="Cyan">
                <color rgba="0 1.0 1.0 1.0"/>
            </material>
        </visual>
        <collision>
            <origin xyz="-1.8549598277666366 2.446965052237946 -2.1024105786332243" rpy="0 0 0"/>
            <geometry>
                <box size="3.709919655533273 4.893930104475892 4.204821157266449" />
            </geometry>
        </collision>
    </link>
</robot>