<robot name = "robot">
    <link name="Body">
        <inertial>
            <origin xyz="0 0 3.339331485479523" rpy="0 0 0"/>
            <mass value="1" />
            <inertia ixx="100" ixy="0" ixz="0" iyy="100" iyz="0" izz="100" />
        </inertial>
        <visual>
            <origin xyz="0 0 3.339331485479523" rpy="0 0 0"/>
            <geometry>
                <box size="1.6859050925007417 2.0337129822308193 2.540166879451759" />
            </geometry>
            <material name="Cyan">
                <color rgba="0 1.0 1.0 1.0"/>
            </material>
        </visual>
        <collision>
            <origin xyz="0 0 3.339331485479523" rpy="0 0 0"/>
            <geometry>
                <box size="1.6859050925007417 2.0337129822308193 2.540166879451759" />
            </geometry>
        </collision>
    </link>
    <joint name="Body_Leg1" type="revolute">
       <parent link="Body"/>
       <child  link="Leg1"/>
       <origin rpy="0 0 0" xyz="-0.8429525462503709 -1.0168564911154097 2.0692480457536435" />
       <axis xyz="0 1 0"/>
       <limit effort="0.0" lower="-3.14159" upper="3.14159" velocity="0.0"/>
    </joint>
    <link name="Leg1">
        <inertial>
            <origin xyz="-1.2466682457815792 -1.9319572337734183 -1.0346240228768218" rpy="0 0 0"/>
            <mass value="1" />
            <inertia ixx="100" ixy="0" ixz="0" iyy="100" iyz="0" izz="100" />
        </inertial>
        <visual>
            <origin xyz="-1.2466682457815792 -1.9319572337734183 -1.0346240228768218" rpy="0 0 0"/>
            <geometry>
                <box size="2.4933364915631584 3.8639144675468367 2.0692480457536435" />
            </geometry>
            <material name="Cyan">
                <color rgba="0 1.0 1.0 1.0"/>
            </material>
        </visual>
        <collision>
            <origin xyz="-1.2466682457815792 -1.9319572337734183 -1.0346240228768218" rpy="0 0 0"/>
            <geometry>
                <box size="2.4933364915631584 3.8639144675468367 2.0692480457536435" />
            </geometry>
        </collision>
    </link>
    <joint name="Body_Leg2" type="revolute">
       <parent link="Body"/>
       <child  link="Leg2"/>
       <origin rpy="0 0 0" xyz="0.8429525462503709 -1.0168564911154097 2.0692480457536435" />
       <axis xyz="0 1 0"/>
       <limit effort="0.0" lower="-3.14159" upper="3.14159" velocity="0.0"/>
    </joint>
    <link name="Leg2">
        <inertial>
            <origin xyz="2.3494203338939816 -1.1108778706118214 -0.3120490580616389" rpy="0 0 0"/>
            <mass value="1" />
            <inertia ixx="100" ixy="0" ixz="0" iyy="100" iyz="0" izz="100" />
        </inertial>
        <visual>
            <origin xyz="2.3494203338939816 -1.1108778706118214 -0.3120490580616389" rpy="0 0 0"/>
            <geometry>
                <box size="4.698840667787963 2.221755741223643 0.6240981161232778" />
            </geometry>
            <material name="Cyan">
                <color rgba="0 1.0 1.0 1.0"/>
            </material>
        </visual>
        <collision>
            <origin xyz="2.3494203338939816 -1.1108778706118214 -0.3120490580616389" rpy="0 0 0"/>
            <geometry>
                <box size="4.698840667787963 2.221755741223643 0.6240981161232778" />
            </geometry>
        </collision>
    </link>
    <joint name="Body_Leg3" type="revolute">
       <parent link="Body"/>
       <child  link="Leg3"/>
       <origin rpy="0 0 0" xyz="0.8429525462503709 1.0168564911154097 2.0692480457536435" />
       <axis xyz="0 1 0"/>
       <limit effort="0.0" lower="-3.14159" upper="3.14159" velocity="0.0"/>
    </joint>
    <link name="Leg3">
        <inertial>
            <origin xyz="0.1732509900297899 2.3449640470151962 -0.5337863721930186" rpy="0 0 0"/>
            <mass value="1" />
            <inertia ixx="100" ixy="0" ixz="0" iyy="100" iyz="0" izz="100" />
        </inertial>
        <visual>
            <origin xyz="0.1732509900297899 2.3449640470151962 -0.5337863721930186" rpy="0 0 0"/>
            <geometry>
                <box size="0.3465019800595798 4.6899280940303925 1.0675727443860372" />
            </geometry>
            <material name="Cyan">
                <color rgba="0 1.0 1.0 1.0"/>
            </material>
        </visual>
        <collision>
            <origin xyz="0.1732509900297899 2.3449640470151962 -0.5337863721930186" rpy="0 0 0"/>
            <geometry>
                <box size="0.3465019800595798 4.6899280940303925 1.0675727443860372" />
            </geometry>
        </collision>
    </link>
    <joint name="Body_Leg4" type="revolute">
       <parent link="Body"/>
       <child  link="Leg4"/>
       <origin rpy="0 0 0" xyz="-0.8429525462503709 1.0168564911154097 2.0692480457536435" />
       <axis xyz="0 1 0"/>
       <limit effort="0.0" lower="-3.14159" upper="3.14159" velocity="0.0"/>
    </joint>
    <link name="Leg4">
        <inertial>
            <origin xyz="-0.9049405458413301 1.323146644952178 -0.020244014519978093" rpy="0 0 0"/>
            <mass value="1" />
            <inertia ixx="100" ixy="0" ixz="0" iyy="100" iyz="0" izz="100" />
        </inertial>
        <visual>
            <origin xyz="-0.9049405458413301 1.323146644952178 -0.020244014519978093" rpy="0 0 0"/>
            <geometry>
                <box size="1.8098810916826602 2.646293289904356 0.040488029039956186" />
            </geometry>
            <material name="Cyan">
                <color rgba="0 1.0 1.0 1.0"/>
            </material>
        </visual>
        <collision>
            <origin xyz="-0.9049405458413301 1.323146644952178 -0.020244014519978093" rpy="0 0 0"/>
            <geometry>
                <box size="1.8098810916826602 2.646293289904356 0.040488029039956186" />
            </geometry>
        </collision>
    </link>
</robot>