<robot name = "robot">
    <link name="Body">
        <inertial>
            <origin xyz="0 0 4.863345528708637" rpy="0 0 0"/>
            <mass value="1" />
            <inertia ixx="100" ixy="0" ixz="0" iyy="100" iyz="0" izz="100" />
        </inertial>
        <visual>
            <origin xyz="0 0 4.863345528708637" rpy="0 0 0"/>
            <geometry>
                <box size="0.37018524362781247 0.004739045172341139 1.7837117058463259" />
            </geometry>
            <material name="Cyan">
                <color rgba="0 1.0 1.0 1.0"/>
            </material>
        </visual>
        <collision>
            <origin xyz="0 0 4.863345528708637" rpy="0 0 0"/>
            <geometry>
                <box size="0.37018524362781247 0.004739045172341139 1.7837117058463259" />
            </geometry>
        </collision>
    </link>
    <joint name="Body_Leg1" type="revolute">
       <parent link="Body"/>
       <child  link="Leg1"/>
       <origin rpy="0 0 0" xyz="-0.18509262181390623 -0.0023695225861705693 3.9714896757854734" />
       <axis xyz="0 1 0"/>
       <limit effort="0.0" lower="-3.14159" upper="3.14159" velocity="0.0"/>
    </joint>
    <link name="Leg1">
        <inertial>
            <origin xyz="-0.8858651906208226 -1.5371115585631936 -1.9857448378927367" rpy="0 0 0"/>
            <mass value="1" />
            <inertia ixx="100" ixy="0" ixz="0" iyy="100" iyz="0" izz="100" />
        </inertial>
        <visual>
            <origin xyz="-0.8858651906208226 -1.5371115585631936 -1.9857448378927367" rpy="0 0 0"/>
            <geometry>
                <box size="1.7717303812416452 3.074223117126387 3.9714896757854734" />
            </geometry>
            <material name="Cyan">
                <color rgba="0 1.0 1.0 1.0"/>
            </material>
        </visual>
        <collision>
            <origin xyz="-0.8858651906208226 -1.5371115585631936 -1.9857448378927367" rpy="0 0 0"/>
            <geometry>
                <box size="1.7717303812416452 3.074223117126387 3.9714896757854734" />
            </geometry>
        </collision>
    </link>
    <joint name="Body_Leg2" type="revolute">
       <parent link="Body"/>
       <child  link="Leg2"/>
       <origin rpy="0 0 0" xyz="0.18509262181390623 -0.0023695225861705693 3.9714896757854734" />
       <axis xyz="0 1 0"/>
       <limit effort="0.0" lower="-3.14159" upper="3.14159" velocity="0.0"/>
    </joint>
    <link name="Leg2">
        <inertial>
            <origin xyz="0.7443084315708703 -0.568005670883621 -0.8222590697001042" rpy="0 0 0"/>
            <mass value="1" />
            <inertia ixx="100" ixy="0" ixz="0" iyy="100" iyz="0" izz="100" />
        </inertial>
        <visual>
            <origin xyz="0.7443084315708703 -0.568005670883621 -0.8222590697001042" rpy="0 0 0"/>
            <geometry>
                <box size="1.4886168631417407 1.136011341767242 1.6445181394002084" />
            </geometry>
            <material name="Cyan">
                <color rgba="0 1.0 1.0 1.0"/>
            </material>
        </visual>
        <collision>
            <origin xyz="0.7443084315708703 -0.568005670883621 -0.8222590697001042" rpy="0 0 0"/>
            <geometry>
                <box size="1.4886168631417407 1.136011341767242 1.6445181394002084" />
            </geometry>
        </collision>
    </link>
    <joint name="Body_Leg3" type="revolute">
       <parent link="Body"/>
       <child  link="Leg3"/>
       <origin rpy="0 0 0" xyz="0.18509262181390623 0.0023695225861705693 3.9714896757854734" />
       <axis xyz="0 1 0"/>
       <limit effort="0.0" lower="-3.14159" upper="3.14159" velocity="0.0"/>
    </joint>
    <link name="Leg3">
        <inertial>
            <origin xyz="1.2275227323182059 0.1718709336995855 -0.5532336351986489" rpy="0 0 0"/>
            <mass value="1" />
            <inertia ixx="100" ixy="0" ixz="0" iyy="100" iyz="0" izz="100" />
        </inertial>
        <visual>
            <origin xyz="1.2275227323182059 0.1718709336995855 -0.5532336351986489" rpy="0 0 0"/>
            <geometry>
                <box size="2.4550454646364117 0.343741867399171 1.1064672703972978" />
            </geometry>
            <material name="Cyan">
                <color rgba="0 1.0 1.0 1.0"/>
            </material>
        </visual>
        <collision>
            <origin xyz="1.2275227323182059 0.1718709336995855 -0.5532336351986489" rpy="0 0 0"/>
            <geometry>
                <box size="2.4550454646364117 0.343741867399171 1.1064672703972978" />
            </geometry>
        </collision>
    </link>
    <joint name="Body_Leg4" type="revolute">
       <parent link="Body"/>
       <child  link="Leg4"/>
       <origin rpy="0 0 0" xyz="-0.18509262181390623 0.0023695225861705693 3.9714896757854734" />
       <axis xyz="0 1 0"/>
       <limit effort="0.0" lower="-3.14159" upper="3.14159" velocity="0.0"/>
    </joint>
    <link name="Leg4">
        <inertial>
            <origin xyz="-0.20041389272209525 2.3206765729077548 -1.8560055903761201" rpy="0 0 0"/>
            <mass value="1" />
            <inertia ixx="100" ixy="0" ixz="0" iyy="100" iyz="0" izz="100" />
        </inertial>
        <visual>
            <origin xyz="-0.20041389272209525 2.3206765729077548 -1.8560055903761201" rpy="0 0 0"/>
            <geometry>
                <box size="0.4008277854441905 4.6413531458155095 3.7120111807522402" />
            </geometry>
            <material name="Cyan">
                <color rgba="0 1.0 1.0 1.0"/>
            </material>
        </visual>
        <collision>
            <origin xyz="-0.20041389272209525 2.3206765729077548 -1.8560055903761201" rpy="0 0 0"/>
            <geometry>
                <box size="0.4008277854441905 4.6413531458155095 3.7120111807522402" />
            </geometry>
        </collision>
    </link>
</robot>