<robot name = "robot">
    <link name="Body">
        <inertial>
            <origin xyz="0 0 6.478859905709529" rpy="0 0 0"/>
            <mass value="1" />
            <inertia ixx="100" ixy="0" ixz="0" iyy="100" iyz="0" izz="100" />
        </inertial>
        <visual>
            <origin xyz="0 0 6.478859905709529" rpy="0 0 0"/>
            <geometry>
                <box size="3.00553918342309 0.17536607627353484 4.616851974203088" />
            </geometry>
            <material name="Cyan">
                <color rgba="0 1.0 1.0 1.0"/>
            </material>
        </visual>
        <collision>
            <origin xyz="0 0 6.478859905709529" rpy="0 0 0"/>
            <geometry>
                <box size="3.00553918342309 0.17536607627353484 4.616851974203088" />
            </geometry>
        </collision>
    </link>
    <joint name="Body_Leg1" type="revolute">
       <parent link="Body"/>
       <child  link="Leg1"/>
       <origin rpy="0 0 0" xyz="-1.502769591711545 -0.08768303813676742 4.170433918607984" />
       <axis xyz="0 1 0"/>
       <limit effort="0.0" lower="-3.14159" upper="3.14159" velocity="0.0"/>
    </joint>
    <link name="Leg1">
        <inertial>
            <origin xyz="-2.4162486502030975 -0.7054858038136613 -1.3174288807070502" rpy="0 0 0"/>
            <mass value="1" />
            <inertia ixx="100" ixy="0" ixz="0" iyy="100" iyz="0" izz="100" />
        </inertial>
        <visual>
            <origin xyz="-2.4162486502030975 -0.7054858038136613 -1.3174288807070502" rpy="0 0 0"/>
            <geometry>
                <box size="4.832497300406195 1.4109716076273227 2.6348577614141004" />
            </geometry>
            <material name="Cyan">
                <color rgba="0 1.0 1.0 1.0"/>
            </material>
        </visual>
        <collision>
            <origin xyz="-2.4162486502030975 -0.7054858038136613 -1.3174288807070502" rpy="0 0 0"/>
            <geometry>
                <box size="4.832497300406195 1.4109716076273227 2.6348577614141004" />
            </geometry>
        </collision>
    </link>
    <joint name="Body_Leg2" type="revolute">
       <parent link="Body"/>
       <child  link="Leg2"/>
       <origin rpy="0 0 0" xyz="1.502769591711545 -0.08768303813676742 4.170433918607984" />
       <axis xyz="0 1 0"/>
       <limit effort="0.0" lower="-3.14159" upper="3.14159" velocity="0.0"/>
    </joint>
    <link name="Leg2">
        <inertial>
            <origin xyz="1.8099042007921073 -1.3310760640233728 -2.085216959303992" rpy="0 0 0"/>
            <mass value="1" />
            <inertia ixx="100" ixy="0" ixz="0" iyy="100" iyz="0" izz="100" />
        </inertial>
        <visual>
            <origin xyz="1.8099042007921073 -1.3310760640233728 -2.085216959303992" rpy="0 0 0"/>
            <geometry>
                <box size="3.6198084015842147 2.6621521280467455 4.170433918607984" />
            </geometry>
            <material name="Cyan">
                <color rgba="0 1.0 1.0 1.0"/>
            </material>
        </visual>
        <collision>
            <origin xyz="1.8099042007921073 -1.3310760640233728 -2.085216959303992" rpy="0 0 0"/>
            <geometry>
                <box size="3.6198084015842147 2.6621521280467455 4.170433918607984" />
            </geometry>
        </collision>
    </link>
    <joint name="Body_Leg3" type="revolute">
       <parent link="Body"/>
       <child  link="Leg3"/>
       <origin rpy="0 0 0" xyz="1.502769591711545 0.08768303813676742 4.170433918607984" />
       <axis xyz="0 1 0"/>
       <limit effort="0.0" lower="-3.14159" upper="3.14159" velocity="0.0"/>
    </joint>
    <link name="Leg3">
        <inertial>
            <origin xyz="1.6034845213517013 0.7021013384160513 -1.994257927332148" rpy="0 0 0"/>
            <mass value="1" />
            <inertia ixx="100" ixy="0" ixz="0" iyy="100" iyz="0" izz="100" />
        </inertial>
        <visual>
            <origin xyz="1.6034845213517013 0.7021013384160513 -1.994257927332148" rpy="0 0 0"/>
            <geometry>
                <box size="3.2069690427034026 1.4042026768321025 3.988515854664296" />
            </geometry>
            <material name="Cyan">
                <color rgba="0 1.0 1.0 1.0"/>
            </material>
        </visual>
        <collision>
            <origin xyz="1.6034845213517013 0.7021013384160513 -1.994257927332148" rpy="0 0 0"/>
            <geometry>
                <box size="3.2069690427034026 1.4042026768321025 3.988515854664296" />
            </geometry>
        </collision>
    </link>
    <joint name="Body_Leg4" type="revolute">
       <parent link="Body"/>
       <child  link="Leg4"/>
       <origin rpy="0 0 0" xyz="-1.502769591711545 0.08768303813676742 4.170433918607984" />
       <axis xyz="0 1 0"/>
       <limit effort="0.0" lower="-3.14159" upper="3.14159" velocity="0.0"/>
    </joint>
    <link name="Leg4">
        <inertial>
            <origin xyz="-1.710904815678946 2.2211610713603083 -1.2416762314795249" rpy="0 0 0"/>
            <mass value="1" />
            <inertia ixx="100" ixy="0" ixz="0" iyy="100" iyz="0" izz="100" />
        </inertial>
        <visual>
            <origin xyz="-1.710904815678946 2.2211610713603083 -1.2416762314795249" rpy="0 0 0"/>
            <geometry>
                <box size="3.421809631357892 4.4423221427206165 2.4833524629590498" />
            </geometry>
            <material name="Cyan">
                <color rgba="0 1.0 1.0 1.0"/>
            </material>
        </visual>
        <collision>
            <origin xyz="-1.710904815678946 2.2211610713603083 -1.2416762314795249" rpy="0 0 0"/>
            <geometry>
                <box size="3.421809631357892 4.4423221427206165 2.4833524629590498" />
            </geometry>
        </collision>
    </link>
</robot>