<robot name = "robot">
    <link name="Body">
        <inertial>
            <origin xyz="0 0 5.655033386274127" rpy="0 0 0"/>
            <mass value="1" />
            <inertia ixx="100" ixy="0" ixz="0" iyy="100" iyz="0" izz="100" />
        </inertial>
        <visual>
            <origin xyz="0 0 5.655033386274127" rpy="0 0 0"/>
            <geometry>
                <box size="4.140002550059431 3.083768184048621 2.6094982220941896" />
            </geometry>
            <material name="Cyan">
                <color rgba="0 1.0 1.0 1.0"/>
            </material>
        </visual>
        <collision>
            <origin xyz="0 0 5.655033386274127" rpy="0 0 0"/>
            <geometry>
                <box size="4.140002550059431 3.083768184048621 2.6094982220941896" />
            </geometry>
        </collision>
    </link>
    <joint name="Body_Leg1" type="revolute">
       <parent link="Body"/>
       <child  link="Leg1"/>
       <origin rpy="0 0 0" xyz="-2.0700012750297154 -1.5418840920243104 4.350284275227032" />
       <axis xyz="0 1 0"/>
       <limit effort="0.0" lower="-3.14159" upper="3.14159" velocity="0.0"/>
    </joint>
    <link name="Leg1">
        <inertial>
            <origin xyz="-0.7095807998392014 -2.3457548887490622 -2.175142137613516" rpy="0 0 0"/>
            <mass value="1" />
            <inertia ixx="100" ixy="0" ixz="0" iyy="100" iyz="0" izz="100" />
        </inertial>
        <visual>
            <origin xyz="-0.7095807998392014 -2.3457548887490622 -2.175142137613516" rpy="0 0 0"/>
            <geometry>
                <box size="1.4191615996784028 4.6915097774981245 4.350284275227032" />
            </geometry>
            <material name="Cyan">
                <color rgba="0 1.0 1.0 1.0"/>
            </material>
        </visual>
        <collision>
            <origin xyz="-0.7095807998392014 -2.3457548887490622 -2.175142137613516" rpy="0 0 0"/>
            <geometry>
                <box size="1.4191615996784028 4.6915097774981245 4.350284275227032" />
            </geometry>
        </collision>
    </link>
    <joint name="Body_Leg2" type="revolute">
       <parent link="Body"/>
       <child  link="Leg2"/>
       <origin rpy="0 0 0" xyz="2.0700012750297154 -1.5418840920243104 4.350284275227032" />
       <axis xyz="0 1 0"/>
       <limit effort="0.0" lower="-3.14159" upper="3.14159" velocity="0.0"/>
    </joint>
    <link name="Leg2">
        <inertial>
            <origin xyz="1.8422523494919094 -0.24928636369740187 -1.3135080896662266" rpy="0 0 0"/>
            <mass value="1" />
            <inertia ixx="100" ixy="0" ixz="0" iyy="100" iyz="0" izz="100" />
        </inertial>
        <visual>
            <origin xyz="1.8422523494919094 -0.24928636369740187 -1.3135080896662266" rpy="0 0 0"/>
            <geometry>
                <box size="3.684504698983819 0.49857272739480374 2.627016179332453" />
            </geometry>
            <material name="Cyan">
                <color rgba="0 1.0 1.0 1.0"/>
            </material>
        </visual>
        <collision>
            <origin xyz="1.8422523494919094 -0.24928636369740187 -1.3135080896662266" rpy="0 0 0"/>
            <geometry>
                <box size="3.684504698983819 0.49857272739480374 2.627016179332453" />
            </geometry>
        </collision>
    </link>
    <joint name="Body_Leg3" type="revolute">
       <parent link="Body"/>
       <child  link="Leg3"/>
       <origin rpy="0 0 0" xyz="2.0700012750297154 1.5418840920243104 4.350284275227032" />
       <axis xyz="0 1 0"/>
       <limit effort="0.0" lower="-3.14159" upper="3.14159" velocity="0.0"/>
    </joint>
    <link name="Leg3">
        <inertial>
            <origin xyz="1.2885086639274599 0.03225059085676024 -0.24030523989973046" rpy="0 0 0"/>
            <mass value="1" />
            <inertia ixx="100" ixy="0" ixz="0" iyy="100" iyz="0" izz="100" />
        </inertial>
        <visual>
            <origin xyz="1.2885086639274599 0.03225059085676024 -0.24030523989973046" rpy="0 0 0"/>
            <geometry>
                <box size="2.5770173278549198 0.06450118171352048 0.4806104797994609" />
            </geometry>
            <material name="Cyan">
                <color rgba="0 1.0 1.0 1.0"/>
            </material>
        </visual>
        <collision>
            <origin xyz="1.2885086639274599 0.03225059085676024 -0.24030523989973046" rpy="0 0 0"/>
            <geometry>
                <box size="2.5770173278549198 0.06450118171352048 0.4806104797994609" />
            </geometry>
        </collision>
    </link>
    <joint name="Body_Leg4" type="revolute">
       <parent link="Body"/>
       <child  link="Leg4"/>
       <origin rpy="0 0 0" xyz="-2.0700012750297154 1.5418840920243104 4.350284275227032" />
       <axis xyz="0 1 0"/>
       <limit effort="0.0" lower="-3.14159" upper="3.14159" velocity="0.0"/>
    </joint>
    <link name="Leg4">
        <inertial>
            <origin xyz="-0.6784504029074403 1.5767526815577324 -0.4941888116006146" rpy="0 0 0"/>
            <mass value="1" />
            <inertia ixx="100" ixy="0" ixz="0" iyy="100" iyz="0" izz="100" />
        </inertial>
        <visual>
            <origin xyz="-0.6784504029074403 1.5767526815577324 -0.4941888116006146" rpy="0 0 0"/>
            <geometry>
                <box size="1.3569008058148806 3.153505363115465 0.9883776232012292" />
            </geometry>
            <material name="Cyan">
                <color rgba="0 1.0 1.0 1.0"/>
            </material>
        </visual>
        <collision>
            <origin xyz="-0.6784504029074403 1.5767526815577324 -0.4941888116006146" rpy="0 0 0"/>
            <geometry>
                <box size="1.3569008058148806 3.153505363115465 0.9883776232012292" />
            </geometry>
        </collision>
    </link>
</robot>